<?xml version="1.0" ?>
<robot name="p_robot" xmlns:xacro="http://www.ros.org/wiki/xacro">

<xacro:include filename="$(find v2_p_robot_description)/urdf/materials.xacro" />
<!-- <xacro:include filename="$(find v2_p_robot_description)/urdf/v2_p_robot.trans" /> -->
<xacro:include filename="$(find v2_p_robot_description)/urdf/v2_p_robot.gazebo" />


<xacro:macro name="p_robot" params="prefix ns">
<link name="base_footprint"/>

<joint name="base_link_joint" type="fixed">
  <origin xyz="0 0 0" rpy="0 0 0" />
  <parent link="base_footprint" />
  <child link="base_link" />
</joint>

<link name="base_link">
  <inertial>
    <origin xyz="0.0 7.760716692497141e-17 0.3874887103447449" rpy="0 0 0"/>
    <mass value="648.025446900494"/>
    <inertia ixx="95.322016" iyy="96.804915" izz="44.905223" ixy="0.0" iyz="0.0" ixz="0.0"/>
  </inertial>
  <visual>
    <origin xyz="0 0 0" rpy="0 0 0"/>
    <geometry>
      <mesh filename="file://$(find v2_p_robot_description)/meshes/base_link.stl" scale="0.001 0.001 0.001"/>
    </geometry>
    <material name="silver"/>
  </visual>
  <collision>
    <origin xyz="0 0 0" rpy="0 0 0"/>
    <geometry>
      <mesh filename="file://$(find v2_p_robot_description)/meshes/base_link.stl" scale="0.001 0.001 0.001"/>
    </geometry>
  </collision>
</link>

<link name="rear_left_wheel_1">
  <inertial>
    <origin xyz="1.0547118733938987e-14 0.030000000000000027 0.0" rpy="0 0 0"/>
    <mass value="1.7354786136960725"/>
    <inertia ixx="0.004903" iyy="0.008764" izz="0.004903" ixy="0.0" iyz="0.0" ixz="0.0"/>
  </inertial>
  <visual>
    <origin xyz="0.25 -0.355 -0.1" rpy="0 0 0"/>
    <geometry>
      <mesh filename="file://$(find v2_p_robot_description)/meshes/rear_left_wheel_1.stl" scale="0.001 0.001 0.001"/>
    </geometry>
    <material name="silver"/>
  </visual>
  <collision>
    <origin xyz="0.25 -0.355 -0.1" rpy="0 0 0"/>
    <geometry>
      <mesh filename="file://$(find v2_p_robot_description)/meshes/rear_left_wheel_1.stl" scale="0.001 0.001 0.001"/>
    </geometry>
  </collision>
</link>

<link name="rear_right_wheel_1">
  <inertial>
    <origin xyz="-5.551115123125783e-17 -0.030000000000000027 -1.0560996521746802e-14" rpy="0 0 0"/>
    <mass value="1.7354786136960725"/>
    <inertia ixx="0.004903" iyy="0.008764" izz="0.004903" ixy="0.0" iyz="-0.0" ixz="-0.0"/>
  </inertial>
  <visual>
    <origin xyz="0.25 0.355 -0.1" rpy="0 0 0"/>
    <geometry>
      <mesh filename="file://$(find v2_p_robot_description)/meshes/rear_right_wheel_1.stl" scale="0.001 0.001 0.001"/>
    </geometry>
    <material name="silver"/>
  </visual>
  <collision>
    <origin xyz="0.25 0.355 -0.1" rpy="0 0 0"/>
    <geometry>
      <mesh filename="file://$(find v2_p_robot_description)/meshes/rear_right_wheel_1.stl" scale="0.001 0.001 0.001"/>
    </geometry>
  </collision>
</link>

<link name="front_right_wheel_1">
  <inertial>
    <origin xyz="-1.0547118733938987e-14 -0.030000000000000027 0.0" rpy="0 0 0"/>
    <mass value="1.7354786136960725"/>
    <inertia ixx="0.004903" iyy="0.008764" izz="0.004903" ixy="-0.0" iyz="-0.0" ixz="0.0"/>
  </inertial>
  <visual>
    <origin xyz="-0.25 0.355 -0.1" rpy="0 0 0"/>
    <geometry>
      <mesh filename="file://$(find v2_p_robot_description)/meshes/front_right_wheel_1.stl" scale="0.001 0.001 0.001"/>
    </geometry>
    <material name="silver"/>
  </visual>
  <collision>
    <origin xyz="-0.25 0.355 -0.1" rpy="0 0 0"/>
    <geometry>
      <mesh filename="file://$(find v2_p_robot_description)/meshes/front_right_wheel_1.stl" scale="0.001 0.001 0.001"/>
    </geometry>
  </collision>
</link>

<link name="front_left_wheel_1">
  <inertial>
    <origin xyz="-1.0547118733938987e-14 0.030000000000000027 0.0" rpy="0 0 0"/>
    <mass value="1.7354786136960725"/>
    <inertia ixx="0.004903" iyy="0.008764" izz="0.004903" ixy="0.0" iyz="0.0" ixz="0.0"/>
  </inertial>
  <visual>
    <origin xyz="-0.25 -0.355 -0.1" rpy="0 0 0"/>
    <geometry>
      <mesh filename="file://$(find v2_p_robot_description)/meshes/front_left_wheel_1.stl" scale="0.001 0.001 0.001"/>
    </geometry>
    <material name="silver"/>
  </visual>
  <collision>
    <origin xyz="-0.25 -0.355 -0.1" rpy="0 0 0"/>
    <geometry>
      <mesh filename="file://$(find v2_p_robot_description)/meshes/front_left_wheel_1.stl" scale="0.001 0.001 0.001"/>
    </geometry>
  </collision>
</link>

<link name="lidar_1">
  <inertial>
    <origin xyz="0.0 5.9081868368592146e-18 0.02499999999999991" rpy="0 0 0"/>
    <mass value="1.5105170177541418"/>
    <inertia ixx="0.000777" iyy="0.000777" izz="0.000925" ixy="0.0" iyz="-0.0" ixz="-0.0"/>
  </inertial>
  <visual>
    <origin xyz="-0.0 -0.0 -1.55" rpy="0 0 0"/>
    <geometry>
      <mesh filename="file://$(find v2_p_robot_description)/meshes/lidar_1.stl" scale="0.001 0.001 0.001"/>
    </geometry>
    <material name="silver"/>
  </visual>
  <collision>
    <origin xyz="-0.0 -0.0 -1.55" rpy="0 0 0"/>
    <geometry>
      <mesh filename="file://$(find v2_p_robot_description)/meshes/lidar_1.stl" scale="0.001 0.001 0.001"/>
    </geometry>
  </collision>
</link>

<link name="torso_1">
  <inertial>
    <origin xyz="0.0 0.15000000000000002 0.010000000000000009" rpy="0 0 0"/>
    <mass value="9.42"/>
    <inertia ixx="0.070964" iyy="0.031714" izz="0.10205" ixy="0.0" iyz="0.0" ixz="0.0"/>
  </inertial>
  <visual>
    <origin xyz="-0.0 -0.05 -0.45" rpy="0 0 0"/>
    <geometry>
      <mesh filename="file://$(find v2_p_robot_description)/meshes/torso_1.stl" scale="0.001 0.001 0.001"/>
    </geometry>
    <material name="silver"/>
  </visual>
  <collision>
    <origin xyz="-0.0 -0.05 -0.45" rpy="0 0 0"/>
    <geometry>
      <mesh filename="file://$(find v2_p_robot_description)/meshes/torso_1.stl" scale="0.001 0.001 0.001"/>
    </geometry>
  </collision>
</link>

<joint name="rear_left_wheel_joint" type="continuous">
  <origin xyz="-0.25 0.355 0.1" rpy="0 0 0"/>
  <parent link="base_link"/>
  <child link="rear_left_wheel_1"/>
  <axis xyz="0.0 1.0 0.0"/>
</joint>

<joint name="rear_right_wheel_joint" type="continuous">
  <origin xyz="-0.25 -0.355 0.1" rpy="0 0 0"/>
  <parent link="base_link"/>
  <child link="rear_right_wheel_1"/>
  <axis xyz="0.0 1.0 0.0"/>
</joint>

<joint name="front_right_wheel_joint" type="continuous">
  <origin xyz="0.25 -0.355 0.1" rpy="0 0 0"/>
  <parent link="base_link"/>
  <child link="front_right_wheel_1"/>
  <axis xyz="0.0 1.0 0.0"/>
</joint>

<joint name="front_left_wheel_joint" type="continuous">
  <origin xyz="0.25 0.355 0.1" rpy="0 0 0"/>
  <parent link="base_link"/>
  <child link="front_left_wheel_1"/>
  <axis xyz="0.0 1.0 0.0"/>
</joint>

<joint name="lidar_joint" type="fixed">
  <origin xyz="0.0 0.0 1.55" rpy="0 0 0"/>
  <parent link="base_link"/>
  <child link="lidar_1"/>
</joint>

<joint name="torso_joint" type="fixed">
  <origin xyz="0.0 0.05 0.45" rpy="0 0 0"/>
  <parent link="base_link"/>
  <child link="torso_1"/>
  <axis xyz="0.0 0.0 1.0"/>
  <limit upper="1.1" lower="0.0" effort="100" velocity="100"/>
</joint>


    <xacro:arg name="name" default="ur"/>
    <!-- import main macro -->
    <xacro:include filename="$(find ur_description)/urdf/ur_macro.xacro"/>

    <!-- possible 'ur_type' values: ur3, ur3e, ur5, ur5e, ur10, ur10e, ur16e, ur20 -->
    <!-- the default value should raise an error in case this was called without defining the type -->
    <xacro:arg name="ur_type" default="ur10e"/>

    <!-- parameters -->
    <xacro:arg name="tf_prefix" default="ur_" />
    <xacro:arg name="joint_limit_params" default="$(find ur_description)/config/$(arg ur_type)/joint_limits.yaml"/>
    <xacro:arg name="kinematics_params" default="$(find ur_description)/config/$(arg ur_type)/default_kinematics.yaml"/>
    <xacro:arg name="physical_params" default="$(find ur_description)/config/$(arg ur_type)/physical_parameters.yaml"/>
    <xacro:arg name="visual_params" default="$(find ur_description)/config/$(arg ur_type)/visual_parameters.yaml"/>
    <xacro:arg name="transmission_hw_interface" default=""/>
    <xacro:arg name="safety_limits" default="true"/> <!--false-->
    <xacro:arg name="safety_pos_margin" default="0.15"/>
    <xacro:arg name="safety_k_position" default="20"/>
    <!-- ros2_control related parameters -->
    <xacro:arg name="headless_mode" default="false" />
    <xacro:arg name="robot_ip" default="192.168.12.245" />
    <xacro:arg name="script_filename" default=""/>
    <xacro:arg name="output_recipe_filename" default=""/>
    <xacro:arg name="input_recipe_filename" default=""/>
    <xacro:arg name="reverse_ip" default="0.0.0.0"/>
    <xacro:arg name="script_command_port" default="50004"/>
    <xacro:arg name="reverse_port" default="50001"/>
    <xacro:arg name="script_sender_port" default="50002"/>
    <xacro:arg name="trajectory_port" default="50003"/>
    <!--   tool communication related parameters-->
    <xacro:arg name="use_tool_communication" default="false" />
    <xacro:arg name="tool_voltage" default="0" />
    <xacro:arg name="tool_parity" default="0" />
    <xacro:arg name="tool_baud_rate" default="115200" />
    <xacro:arg name="tool_stop_bits" default="1" />
    <xacro:arg name="tool_rx_idle_chars" default="1.5" />
    <xacro:arg name="tool_tx_idle_chars" default="3.5" />
    <xacro:arg name="tool_device_name" default="/tmp/ttyUR" />
    <xacro:arg name="tool_tcp_port" default="54321" />

      <!-- Simulation parameters -->
    <xacro:arg name="use_fake_hardware" default="false" />
    <xacro:arg name="fake_sensor_commands" default="false" />
    <xacro:arg name="sim_gazebo" default="true" />
    <xacro:arg name="sim_ignition" default="false" />
    <xacro:arg name="simulation_controllers" default="" />

    <!-- initial position for simulations (Fake Hardware, Gazebo, Ignition) -->
    <xacro:arg name="initial_positions_file" default="$(find ur_description)/config/initial_positions.yaml"/>

    <!-- convert to property to use substitution in function -->
    <xacro:property name="initial_positions_file" default="$(arg initial_positions_file)"/>

    <!-- create link fixed to the "world" -->
    <link name="world" />
    
    <joint name="world_joint" type="fixed">
      <parent link="torso_1" />
      <child link="world" />
      <origin xyz="0.0 0.15 0.02" rpy="0 0 0" />
    </joint>
    
    <!-- arm -->
    <xacro:ur_robot
      name="$(arg name)"
      tf_prefix="ur_"
      parent="torso_1"
      joint_limits_parameters_file="$(arg joint_limit_params)"
      kinematics_parameters_file="$(arg kinematics_params)"
      physical_parameters_file="$(arg physical_params)"
      visual_parameters_file="$(arg visual_params)"
      transmission_hw_interface="$(arg transmission_hw_interface)"
      safety_limits="$(arg safety_limits)"
      safety_pos_margin="$(arg safety_pos_margin)"
      safety_k_position="$(arg safety_k_position)"
      use_fake_hardware="$(arg use_fake_hardware)"
      fake_sensor_commands="$(arg fake_sensor_commands)"
      sim_gazebo="true"
      sim_ignition="$(arg sim_ignition)"
      headless_mode="$(arg headless_mode)"
      initial_positions="${xacro.load_yaml(initial_positions_file)}"
      use_tool_communication="$(arg use_tool_communication)"
      tool_voltage="$(arg tool_voltage)"
      tool_parity="$(arg tool_parity)"
      tool_baud_rate="$(arg tool_baud_rate)"
      tool_stop_bits="$(arg tool_stop_bits)"
      tool_rx_idle_chars="$(arg tool_rx_idle_chars)"
      tool_tx_idle_chars="$(arg tool_tx_idle_chars)"
      tool_device_name="$(arg tool_device_name)"
      tool_tcp_port="$(arg tool_tcp_port)"
      robot_ip="$(arg robot_ip)"
      script_filename="$(arg script_filename)"
      output_recipe_filename="$(arg output_recipe_filename)"
      input_recipe_filename="$(arg input_recipe_filename)"
      reverse_ip="$(arg reverse_ip)"
      script_command_port="$(arg script_command_port)"
      reverse_port="$(arg reverse_port)"
      script_sender_port="$(arg script_sender_port)"
      trajectory_port="$(arg trajectory_port)"
      >
      <origin xyz="0.0 0.15 0.02" rpy="0 0 0" /> <!--${0.5 * pi}-->         <!-- position robot in the world -->
    </xacro:ur_robot>

    <xacro:if value="true">
      <!-- Gazebo plugins -->
      <gazebo reference="world">
      </gazebo>
      <gazebo>
        <plugin filename="libgazebo_ros2_control.so" name="gazebo_ros2_control_ur">
          <!-- <parameters>$(arg simulation_controllers)</parameters> -->
          <!-- <parameters>$(find mir_description)/config/diffdrive_controller.yaml</parameters> -->
          <!-- <parameters>$(find ur_simulation_gazebo)/config/ur_controllers.yaml</parameters> -->
          <!-- <parameters>$(find ur_simulation_gazebo)/config/ur_manipulator.yaml</parameters> -->
          <!-- <parameters>$(find mir_description)/config/ur_manipulator.yaml</parameters> -->
        </plugin>
      </gazebo>
    </xacro:if>

</xacro:macro>
</robot>
